<?xml version="1.0"?>

<robot name="test_robot">
  <link name="link0">
    <visual>
        <origin xyz="0 0 0" rpy="0 0 0"/>
        <geometry>
           <mesh filename="/ifs/home/jwternent/RBE3001_Matlab01/src/CAD/Link0.stl"/>
        </geometry>
        <material name="Orange"/>
    </visual>
</link>
  <link name="link1">
    <visual>
        <origin xyz="0 0 0" rpy="0 0 0"/>
        <geometry>
            <mesh filename="package://CAD/Link1.stl"/>
        </geometry>
        <material name="Orange"/>
    </visual>
</link>
  <link name="link2">
    <visual>
        <origin xyz="0 0 0" rpy="0 0 0"/>
        <geometry>
            <mesh filename="package://CAD/Link2.stl"/>
        </geometry>
        <material name="Orange"/>
    </visual>
</link>
  <link name="link3">
    <visual>
        <origin xyz="0 0 0" rpy="0 0 0"/>
        <geometry>
            <mesh filename="package://CAD/Link3.stl"/>
        </geometry>
        <material name="Orange"/>
    </visual>
</link>


  <joint name="joint1" type="continuous">
    <parent link="link0"/>
    <child link="link1"/>
    <origin xyz="0 0 .065" rpy="0 0 0" />
    <axis xyz="0 0 1" />
   
  </joint>

  <joint name="joint2" type="continuous">
    <parent link="link1"/>
    <child link="link2"/>
    <origin xyz="0 0 .135" rpy="1.57 0 0" />
    <axis xyz="0 0 1" />
   
  </joint>

  <joint name="joint3" type="continuous">
    <parent link="link2"/>
    <child link="link3"/>
    <origin xyz=".16928 0 0" rpy="0 0 -1.57" />
    <axis xyz="0 0 1" />
  </joint>

</robot>
